Exception in thread main_thread:
Traceback (most recent call last):
  File "/root/.local/share/virtualenvs/-x-v5uFv0/lib/python3.7/site-packages/urllib3/connection.py", line 160, in _new_conn
    (self._dns_host, self.port), self.timeout, **extra_kw
  File "/root/.local/share/virtualenvs/-x-v5uFv0/lib/python3.7/site-packages/urllib3/util/connection.py", line 84, in create_connection
    raise err
  File "/root/.local/share/virtualenvs/-x-v5uFv0/lib/python3.7/site-packages/urllib3/util/connection.py", line 74, in create_connection
    sock.connect(sa)
TimeoutError: [Errno 110] Connection timed out

During handling of the above exception, another exception occurred:
Traceback (most recent call last):
  File "/root/.local/share/virtualenvs/-x-v5uFv0/lib/python3.7/site-packages/urllib3/connectionpool.py", line 677, in urlopen
    chunked=chunked,
  File "/root/.local/share/virtualenvs/-x-v5uFv0/lib/python3.7/site-packages/urllib3/connectionpool.py", line 381, in _make_request
    self._validate_conn(conn)
  File "/root/.local/share/virtualenvs/-x-v5uFv0/lib/python3.7/site-packages/urllib3/connectionpool.py", line 978, in _validate_conn
    conn.connect()
  File "/root/.local/share/virtualenvs/-x-v5uFv0/lib/python3.7/site-packages/urllib3/connection.py", line 309, in connect
    conn = self._new_conn()
  File "/root/.local/share/virtualenvs/-x-v5uFv0/lib/python3.7/site-packages/urllib3/connection.py", line 172, in _new_conn
    self, "Failed to establish a new connection: %s" % e
urllib3.exceptions.NewConnectionError: <urllib3.connection.HTTPSConnection object at 0x7f7e09fe9250>: Failed to establish a new connection: [Errno 110] Connection timed out

During handling of the above exception, another exception occurred:

Traceback (most recent call last):
  File "/root/.local/share/virtualenvs/-x-v5uFv0/lib/python3.7/site-packages/requests/adapters.py", line 449, in send
    timeout=timeout
  File "/root/.local/share/virtualenvs/-x-v5uFv0/lib/python3.7/site-packages/urllib3/connectionpool.py", line 727, in urlopen
    method, url, error=e, _pool=self, _stacktrace=sys.exc_info()[2]
  File "/root/.local/share/virtualenvs/-x-v5uFv0/lib/python3.7/site-packages/urllib3/util/retry.py", line 446, in increment
    raise MaxRetryError(_pool, url, error or ResponseError(cause))
urllib3.exceptions.MaxRetryError: HTTPSConnectionPool(host='cmp-api.ctwing.cn', port=20164): Max retries exceeded with url: /openapi/v1/prodinst/getSIMList?pageIndex=1 (Caused by NewConnectionError('<urllib3.connection.HTTPSConnection object at 0x7f7e09fe9250>: Failed to establish a new connection: [Errno 110] Connection timed out'))

During handling of the above exception, another exception occurred:
Traceback (most recent call last):
  File "/usr/lib/python3.7/threading.py", line 926, in _bootstrap_inner
    self.run()
  File "/usr/lib/python3.7/threading.py", line 870, in run
    self._target(*self._args, **self._kwargs)
  File "/scripts/quota_monitor.py", line 313, in main_thread_func
    get_iccid_list()
  File "/scripts/quota_monitor.py", line 183, in get_iccid_list
    headers=headers,
  File "/root/.local/share/virtualenvs/-x-v5uFv0/lib/python3.7/site-packages/requests/api.py", line 119, in post
    return request('post', url, data=data, json=json, **kwargs)
  File "/root/.local/share/virtualenvs/-x-v5uFv0/lib/python3.7/site-packages/requests/api.py", line 61, in request
    return session.request(method=method, url=url, **kwargs)
  File "/root/.local/share/virtualenvs/-x-v5uFv0/lib/python3.7/site-packages/requests/sessions.py", line 542, in request
    resp = self.send(prep, **send_kwargs)
  File "/root/.local/share/virtualenvs/-x-v5uFv0/lib/python3.7/site-packages/requests/sessions.py", line 655, in send
    r = adapter.send(request, **kwargs)
  File "/root/.local/share/virtualenvs/-x-v5uFv0/lib/python3.7/site-packages/requests/adapters.py", line 516, in send
    raise ConnectionError(e, request=request)
requests.exceptions.ConnectionError: HTTPSConnectionPool(host='cmp-api.ctwing.cn', port=20164): Max retries exceeded with url: /openapi/v1/prodinst/getSIMList?pageIndex=1 (Caused by NewConnectionError('<urllib3.connection.HTTPSConnection object at 0x7f7e09fe9250>: Failed to establish a new connection: [Errno 110] Connection timed out'))
2023-07-13 11:57:10,056 INFO exited: runtime_alert_scheduler_1 (exit status 0; expected)